Workbook
Name Ad_Spend: 'Engagement summary'!$G$2:$G$1048576
Name Attribute: Table1!$N$2:$N$1048576
Name Campaign_Name: Posts!$O$2:$O$1048576
Name Campaign_Name: Table1!$L$2:$L$1048576
Name Campaign_Name: Task_3.1!$O$2:$O$1048576
Name Campaign_Name: 'Engagement summary'!$J$2:$J$1048576
Name Clicks: Posts!$K$2:$K$1048576
Name Clicks: Table1!$K$2:$K$1048576
Name Clicks: Task_3.1!$K$2:$K$1048576
Name Comments: Posts!$H$2:$H$1048576
Name Comments: Table1!$H$2:$H$1048576
Name Comments: Task_3.1!$H$2:$H$1048576
Name Content_Type: Posts!$D$2:$D$1048576
Name Content_Type: Table1!$D$2:$D$1048576
Name Content_Type: Task_3.1!$D$2:$D$1048576
Name Date: Posts!$C$2:$C$1048576
Name Date: Table1!$C$2:$C$1048576
Name Date: Task_3.1!$C$2:$C$1048576
Name Engagement_rate: Posts!$P$2:$P$1048576
Name Engagement_rate: Table1!$M$2:$M$1048576
Name Engagement_rate: Task_3.1!$P$2:$P$1048576
Name Engagement_Rate: 'Engagement summary'!$F$2:$F$1048576
Name Growth_rate: 'Engagement summary'!$I$2:$I$1048576
Name Hashtags: Table1!$O$2:$O$1048576
Name Hashtags_1: Posts!$M$2:$M$1048576
Name Hashtags_1: Task_3.1!$M$2:$M$1048576
Name Hashtags_2: Posts!$N$2:$N$1048576
Name Hashtags_2: Task_3.1!$N$2:$N$1048576
Name Hashtags_Used: Posts!$L$2:$L$1048576
Name Hashtags_Used: Task_3.1!$L$2:$L$1048576
Name Impressions: Posts!$I$2:$I$1048576
Name Impressions: Table1!$I$2:$I$1048576
Name Impressions: Task_3.1!$I$2:$I$1048576
Name Likes: Posts!$F$2:$F$1048576
Name Likes: Table1!$F$2:$F$1048576
Name Likes: Task_3.1!$F$2:$F$1048576
Name Net_Followers: 'Engagement summary'!$H$2:$H$1048576
Name New_Followers: 'Engagement summary'!$C$2:$C$1048576
Name Period: Posts!$Q$2:$Q$1048576
Name Platform: Posts!$B$2:$B$1048576
Name Platform: Table1!$B$2:$B$1048576
Name Platform: Task_3.1!$B$2:$B$1048576
Name Platform: 'Engagement summary'!$B$2:$B$1048576
Name Post_ID: Posts!$A$2:$A$1048576
Name Post_ID: Table1!$A$2:$A$1048576
Name Post_ID: Task_3.1!$A$2:$A$1048576
Name Post_Text: Posts!$E$2:$E$1048576
Name Post_Text: Table1!$E$2:$E$1048576
Name Post_Text: Task_3.1!$E$2:$E$1048576
Name Reach: Posts!$J$2:$J$1048576
Name Reach: Table1!$J$2:$J$1048576
Name Reach: Task_3.1!$J$2:$J$1048576
Name Shares: Posts!$G$2:$G$1048576
Name Shares: Table1!$G$2:$G$1048576
Name Shares: Task_3.1!$G$2:$G$1048576
Name Slicer_Campaign_Name: #N/A
Name Slicer_Content_Type1: #N/A
Name Slicer_Hashtags1: #N/A
Name Slicer_Platform: #N/A
Name Slicer_Platform1: #N/A

Sheet Task_1
A1: Post ID | B1: Platform | C1: Date | D1: Content Type | E1: Post Text | F1: Likes | G1: Shares | H1: Comments | I1: Impressions | J1: Reach | K1: Clicks | L1: Hashtags Used | M1: Hashtags-1 | N1: Hashtags_2 | O1: Campaign_Name
A2: P001 | B2: Twitter | C2: 45649 | D2: Reel | E2: Check out our latest reel on twitter! | F2: 1461 | G2: 184 | H2: 344 | I2: 21915 | J2: 21675 | K2: 15 | L2: #FutureOfDriving | M2: #AnytimeIsTeslaTime | N2: no data | O2: CybertruckLaunch
A3: P002 | B3: Twitter | C3: 45750 | D3: Text | E3: Check out our latest text on twitter! | F3: 4054 | G3: 389 | H3: 493 | I3: 64864 | J3: 64383 | K3: 117 | L3: #TeslaCoInnovation | M3: #BetterWithTesla | N3: no data | O3: ModelYCampaign
A4: P003 | B4: YouTube | C4: 45789 | D4: Reel | E4: Check out our latest reel on youtube! | F4: 2795 | G4: 105 | H4: 49 | I4: 53105 | J4: 52307 | K4: 204 | L4: #TeslaCoInnovation | M4: no data | N4: no data | O4: FSDUpdate
A5: P004 | B5: Instagram | C5: 45516 | D5: Story | E5: Check out our latest story on instagram! | F5: 2404 | G5: 363 | H5: 138 | I5: 19232 | J5: 18636 | K5: 128 | L5: #EVRevolution | M5: no data | N5: no data | O5: SustainabilityDrive
A6: P005 | B6: YouTube | C6: 45469 | D6: Reel | E6: Check out our latest reel on youtube! | F6: 3557 | G6: 687 | H6: 424 | I6: 71140 | J6: 70701 | K6: 224 | L6: #EVRevolution | M6: #TeslaCoInnovation | N6: no data | O6: CybertruckLaunch
A7: P006 | B7: Facebook | C7: 45596 | D7: Carousel | E7: Check out our latest carousel on facebook! | F7: 2945 | G7: 930 | H7: 355 | I7: 23560 | J7: 23275 | K7: 256 | L7: #TeslaCoInnovation | M7: no data | N7: no data | O7: ModelYCampaign
A8: P007 | B8: Twitter | C8: 45467 | D8: Carousel | E8: Check out our latest carousel on twitter! | F8: 3860 | G8: 201 | H8: 279 | I8: 61760 | J8: 61660 | K8: 235 | L8: #TeslaCoInnovation | M8: no data | N8: no data | O8: ModelYCampaign
A9: P008 | B9: YouTube | C9: 45486 | D9: Image | E9: Check out our latest image on youtube! | F9: 3929 | G9: 262 | H9: 278 | I9: 43219 | J9: 42841 | K9: 39 | L9: #EVRevolution | M9: no data | N9: no data | O9: SustainabilityDrive
A10: P009 | B10: Facebook | C10: 45534 | D10: Text | E10: Check out our latest text on facebook! | F10: 3784 | G10: 808 | H10: 404 | I10: 56760 | J10: 56343 | K10: 131 | L10: #TeslaCoInnovation | M10: no data | N10: no data | O10: ModelYCampaign
A11: P010 | B11: Facebook | C11: 45727 | D11: Image | E11: Check out our latest image on facebook! | F11: 4241 | G11: 902 | H11: 47 | I11: 72097 | J11: 71598 | K11: 167 | L11: #TeslaCoInnovation | M11: no data | N11: no data | O11: ModelYCampaign
A12: P011 | B12: Instagram | C12: 45690 | D12: Story | E12: Check out our latest story on instagram! | F12: 1792 | G12: 614 | H12: 497 | I12: 25088 | J12: 24675 | K12: 65 | L12: #FutureOfDriving | M12: no data | N12: no data | O12: SustainabilityDrive
A13: P012 | B13: Facebook | C13: 45494 | D13: Reel | E13: Check out our latest reel on facebook! | F13: 1946 | G13: 686 | H13: 377 | I13: 23352 | J13: 22982 | K13: 213 | L13: #FutureOfDriving | M13: no data | N13: no data | O13: FSDUpdate
... A301: P300 | B301: Twitter | C301: 45535 | D301: Carousel | E301: Check out our latest carousel on twitter! | F301: 4494 | G301: 717 | H301: 45 | I301: 62916 | J301: 62688 | K301: 191 | L301: #TeslaCoInnovation | M301: #EVRevolution | N301: #BetterWithTesla | O301: CybertruckLaunch

Sheet Task_2.1
A1: Post ID | B1: Platform | C1: Date | D1: Content Type | E1: Post Text | F1: Likes | G1: Shares | H1: Comments | I1: Impressions | J1: Reach | K1: Clicks | L1: Hashtags Used | M1: Hashtags-1 | N1: Hashtags_2 | O1: Campaign_Name | P1: Engagement rate
A2: P001 | B2: Twitter | C2: 45649 | D2: Reel | E2: Check out our latest reel on twitter! | F2: 1461 | G2: 184 | H2: 344 | I2: 21915 | J2: 21675 | K2: 15 | L2: #FutureOfDriving | M2: #AnytimeIsTeslaTime | N2: no data | O2: CybertruckLaunch | P2: =(Table1_14[[#This Row],[Likes]]+Table1_14[[#This Row],[Shares]]+Table1_14[[#This Row],[Comments]])/Table1_14[[#This Row],[Impressions]] -> 0.090759754
A3: P002 | B3: Twitter | C3: 45750 | D3: Text | E3: Check out our latest text on twitter! | F3: 4054 | G3: 389 | H3: 493 | I3: 64864 | J3: 64383 | K3: 117 | L3: #TeslaCoInnovation | M3: #BetterWithTesla | N3: no data | O3: ModelYCampaign | P3: =(Table1_14[[#This Row],[Likes]]+Table1_14[[#This Row],[Shares]]+Table1_14[[#This Row],[Comments]])/Table1_14[[#This Row],[Impressions]] -> 0.076097681
A4: P003 | B4: YouTube | C4: 45789 | D4: Reel | E4: Check out our latest reel on youtube! | F4: 2795 | G4: 105 | H4: 49 | I4: 53105 | J4: 52307 | K4: 204 | L4: #TeslaCoInnovation | M4: no data | N4: no data | O4: FSDUpdate | P4: =(Table1_14[[#This Row],[Likes]]+Table1_14[[#This Row],[Shares]]+Table1_14[[#This Row],[Comments]])/Table1_14[[#This Row],[Impressions]] -> 0.055531494
A5: P004 | B5: Instagram | C5: 45516 | D5: Story | E5: Check out our latest story on instagram! | F5: 2404 | G5: 363 | H5: 138 | I5: 19232 | J5: 18636 | K5: 128 | L5: #EVRevolution | M5: no data | N5: no data | O5: SustainabilityDrive | P5: =(Table1_14[[#This Row],[Likes]]+Table1_14[[#This Row],[Shares]]+Table1_14[[#This Row],[Comments]])/Table1_14[[#This Row],[Impressions]] -> 0.15105033
A6: P005 | B6: YouTube | C6: 45469 | D6: Reel | E6: Check out our latest reel on youtube! | F6: 3557 | G6: 687 | H6: 424 | I6: 71140 | J6: 70701 | K6: 224 | L6: #EVRevolution | M6: #TeslaCoInnovation | N6: no data | O6: CybertruckLaunch | P6: =(Table1_14[[#This Row],[Likes]]+Table1_14[[#This Row],[Shares]]+Table1_14[[#This Row],[Comments]])/Table1_14[[#This Row],[Impressions]] -> 0.065617093 | R6: Instagram has the highest Average Engagement Rate
A7: P006 | B7: Facebook | C7: 45596 | D7: Carousel | E7: Check out our latest carousel on facebook! | F7: 2945 | G7: 930 | H7: 355 | I7: 23560 | J7: 23275 | K7: 256 | L7: #TeslaCoInnovation | M7: no data | N7: no data | O7: ModelYCampaign | P7: =(Table1_14[[#This Row],[Likes]]+Table1_14[[#This Row],[Shares]]+Table1_14[[#This Row],[Comments]])/Table1_14[[#This Row],[Impressions]] -> 0.1795416
A8: P007 | B8: Twitter | C8: 45467 | D8: Carousel | E8: Check out our latest carousel on twitter! | F8: 3860 | G8: 201 | H8: 279 | I8: 61760 | J8: 61660 | K8: 235 | L8: #TeslaCoInnovation | M8: no data | N8: no data | O8: ModelYCampaign | P8: =(Table1_14[[#This Row],[Likes]]+Table1_14[[#This Row],[Shares]]+Table1_14[[#This Row],[Comments]])/Table1_14[[#This Row],[Impressions]] -> 0.070272021
A9: P008 | B9: YouTube | C9: 45486 | D9: Image | E9: Check out our latest image on youtube! | F9: 3929 | G9: 262 | H9: 278 | I9: 43219 | J9: 42841 | K9: 39 | L9: #EVRevolution | M9: no data | N9: no data | O9: SustainabilityDrive | P9: =(Table1_14[[#This Row],[Likes]]+Table1_14[[#This Row],[Shares]]+Table1_14[[#This Row],[Comments]])/Table1_14[[#This Row],[Impressions]] -> 0.1034036 | R9: Row Labels | S9: Average of Engagement rate
A10: P009 | B10: Facebook | C10: 45534 | D10: Text | E10: Check out our latest text on facebook! | F10: 3784 | G10: 808 | H10: 404 | I10: 56760 | J10: 56343 | K10: 131 | L10: #TeslaCoInnovation | M10: no data | N10: no data | O10: ModelYCampaign | P10: =(Table1_14[[#This Row],[Likes]]+Table1_14[[#This Row],[Shares]]+Table1_14[[#This Row],[Comments]])/Table1_14[[#This Row],[Impressions]] -> 0.088019732 | R10: Instagram | S10: 0.19329258
A11: P010 | B11: Facebook | C11: 45727 | D11: Image | E11: Check out our latest image on facebook! | F11: 4241 | G11: 902 | H11: 47 | I11: 72097 | J11: 71598 | K11: 167 | L11: #TeslaCoInnovation | M11: no data | N11: no data | O11: ModelYCampaign | P11: =(Table1_14[[#This Row],[Likes]]+Table1_14[[#This Row],[Shares]]+Table1_14[[#This Row],[Comments]])/Table1_14[[#This Row],[Impressions]] -> 0.071986352 | R11: Twitter | S11: 0.14368407
A12: P011 | B12: Instagram | C12: 45690 | D12: Story | E12: Check out our latest story on instagram! | F12: 1792 | G12: 614 | H12: 497 | I12: 25088 | J12: 24675 | K12: 65 | L12: #FutureOfDriving | M12: no data | N12: no data | O12: SustainabilityDrive | P12: =(Table1_14[[#This Row],[Likes]]+Table1_14[[#This Row],[Shares]]+Table1_14[[#This Row],[Comments]])/Table1_14[[#This Row],[Impressions]] -> 0.11571269 | R12: YouTube | S12: 0.13118494
A13: P012 | B13: Facebook | C13: 45494 | D13: Reel | E13: Check out our latest reel on facebook! | F13: 1946 | G13: 686 | H13: 377 | I13: 23352 | J13: 22982 | K13: 213 | L13: #FutureOfDriving | M13: no data | N13: no data | O13: FSDUpdate | P13: =(Table1_14[[#This Row],[Likes]]+Table1_14[[#This Row],[Shares]]+Table1_14[[#This Row],[Comments]])/Table1_14[[#This Row],[Impressions]] -> 0.12885406 | R13: Facebook | S13: 0.1219729
A14: P013 | B14: YouTube | C14: 45614 | D14: Carousel | E14: Check out our latest carousel on youtube! | F14: 1171 | G14: 286 | H14: 231 | I14: 22249 | J14: 21282 | K14: 114 | L14: #EVRevolution | M14: no data | N14: no data | O14: CybertruckLaunch | P14: =(Table1_14[[#This Row],[Likes]]+Table1_14[[#This Row],[Shares]]+Table1_14[[#This Row],[Comments]])/Table1_14[[#This Row],[Impressions]] -> 0.075868578 | R14: Grand Total | S14: 0.14828272
A15: P014 | B15: Facebook | C15: 45704 | D15: Story | E15: Check out our latest story on facebook! | F15: 4242 | G15: 555 | H15: 131 | I15: 33936 | J15: 33802 | K15: 265 | L15: #FutureOfDriving | M15: no data | N15: no data | O15: unknown | P15: =(Table1_14[[#This Row],[Likes]]+Table1_14[[#This Row],[Shares]]+Table1_14[[#This Row],[Comments]])/Table1_14[[#This Row],[Impressions]] -> 0.14521452
A16: P015 | B16: Facebook | C16: 45589 | D16: Video | E16: Check out our latest video on facebook! | F16: 3888 | G16: 604 | H16: 128 | I16: 77760 | J16: 77167 | K16: 20 | L16: #FutureOfDriving | M16: no data | N16: no data | O16: CybertruckLaunch | P16: =(Table1_14[[#This Row],[Likes]]+Table1_14[[#This Row],[Shares]]+Table1_14[[#This Row],[Comments]])/Table1_14[[#This Row],[Impressions]] -> 0.05941358
A17: P016 | B17: Facebook | C17: 45530 | D17: Text | E17: Check out our latest text on facebook! | F17: 3452 | G17: 377 | H17: 360 | I17: 55232 | J17: 55075 | K17: 87 | L17: #FutureOfDriving | M17: no data | N17: no data | O17: FSDUpdate | P17: =(Table1_14[[#This Row],[Likes]]+Table1_14[[#This Row],[Shares]]+Table1_14[[#This Row],[Comments]])/Table1_14[[#This Row],[Impressions]] -> 0.075843714
A18: P017 | B18: Facebook | C18: 45782 | D18: Text | E18: Check out our latest text on facebook! | F18: 4441 | G18: 511 | H18: 70 | I18: 53292 | J18: 53082 | K18: 159 | L18: #EVRevolution | M18: no data | N18: no data | O18: SustainabilityDrive | P18: =(Table1_14[[#This Row],[Likes]]+Table1_14[[#This Row],[Shares]]+Table1_14[[#This Row],[Comments]])/Table1_14[[#This Row],[Impressions]] -> 0.094235533
A19: P018 | B19: Instagram | C19: 45523 | D19: Reel | E19: Check out our latest reel on instagram! | F19: 3000 | G19: 382 | H19: 325 | I19: 36000 | J19: 35819 | K19: 19 | L19: #FutureOfDriving | M19: no data | N19: no data | O19: CybertruckLaunch | P19: =(Table1_14[[#This Row],[Likes]]+Table1_14[[#This Row],[Shares]]+Table1_14[[#This Row],[Comments]])/Table1_14[[#This Row],[Impressions]] -> 0.10297222
A20: P019 | B20: Instagram | C20: 45466 | D20: Video | E20: Check out our latest video on instagram! | F20: 1071 | G20: 519 | H20: 22 | I20: 16065 | J20: 15865 | K20: 103 | L20: #TeslaCoInnovation | M20: no data | N20: no data | O20: SustainabilityDrive | P20: =(Table1_14[[#This Row],[Likes]]+Table1_14[[#This Row],[Shares]]+Table1_14[[#This Row],[Comments]])/Table1_14[[#This Row],[Impressions]] -> 0.10034236
A21: P020 | B21: Instagram | C21: 45544 | D21: Carousel | E21: Check out our latest carousel on instagram! | F21: 4054 | G21: 488 | H21: 373 | I21: 77026 | J21: 76881 | K21: 25 | L21: #TeslaCoInnovation | M21: no data | N21: no data | O21: CybertruckLaunch | P21: =(Table1_14[[#This Row],[Likes]]+Table1_14[[#This Row],[Shares]]+Table1_14[[#This Row],[Comments]])/Table1_14[[#This Row],[Impressions]] -> 0.063809623
A22: P021 | B22: Instagram | C22: 45661 | D22: Reel | E22: Check out our latest reel on instagram! | F22: 4838 | G22: 640 | H22: 128 | I22: 72570 | J22: 72396 | K22: 83 | L22: #FutureOfDriving | M22: no data | N22: no data | O22: SustainabilityDrive | P22: =(Table1_14[[#This Row],[Likes]]+Table1_14[[#This Row],[Shares]]+Table1_14[[#This Row],[Comments]])/Table1_14[[#This Row],[Impressions]] -> 0.077249552
A23: P022 | B23: Facebook | C23: 45715 | D23: Text | E23: Check out our latest text on facebook! | F23: 1570 | G23: 187 | H23: 260 | I23: 25120 | J23: 24613 | K23: 133 | L23: #TeslaCoInnovation | M23: no data | N23: no data | O23: SustainabilityDrive | P23: =(Table1_14[[#This Row],[Likes]]+Table1_14[[#This Row],[Shares]]+Table1_14[[#This Row],[Comments]])/Table1_14[[#This Row],[Impressions]] -> 0.080294586
A24: P023 | B24: Facebook | C24: 45602 | D24: Video | E24: Check out our latest video on facebook! | F24: 1606 | G24: 547 | H24: 316 | I24: 32120 | J24: 31736 | K24: 225 | L24: #TeslaCoInnovation | M24: #AnytimeIsTeslaTime | N24: no data | O24: ModelYCampaign | P24: =(Table1_14[[#This Row],[Likes]]+Table1_14[[#This Row],[Shares]]+Table1_14[[#This Row],[Comments]])/Table1_14[[#This Row],[Impressions]] -> 0.076867995
A25: P024 | B25: Facebook | C25: 45680 | D25: Video | E25: Check out our latest video on facebook! | F25: 3961 | G25: 761 | H25: 131 | I25: 67337 | J25: 66615 | K25: 161 | L25: #FutureOfDriving | M25: no data | N25: no data | O25: FSDUpdate | P25: =(Table1_14[[#This Row],[Likes]]+Table1_14[[#This Row],[Shares]]+Table1_14[[#This Row],[Comments]])/Table1_14[[#This Row],[Impressions]] -> 0.072070333
A26: P025 | B26: Twitter | C26: 45757 | D26: Carousel | E26: Check out our latest carousel on twitter! | F26: 3128 | G26: 211 | H26: 197 | I26: 59432 | J26: 59182 | K26: 238 | L26: #EVRevolution | M26: no data | N26: no data | O26: unknown | P26: =(Table1_14[[#This Row],[Likes]]+Table1_14[[#This Row],[Shares]]+Table1_14[[#This Row],[Comments]])/Table1_14[[#This Row],[Impressions]] -> 0.059496568
... A301: P300 | B301: Twitter | C301: 45535 | D301: Carousel | E301: Check out our latest carousel on twitter! | F301: 4494 | G301: 717 | H301: 45 | I301: 62916 | J301: 62688 | K301: 191 | L301: #TeslaCoInnovation | M301: #EVRevolution | N301: #BetterWithTesla | O301: CybertruckLaunch | P301: =(Table1_14[[#This Row],[Likes]]+Table1_14[[#This Row],[Shares]]+Table1_14[[#This Row],[Comments]])/Table1_14[[#This Row],[Impressions]] -> 0.083539958

Sheet Task_2.2
E1: TOP 10 POSTS WITH HIGHEST ENGAGEMENT RATE(HIGHLIGHTED IN GREEN)
A2: Post ID | B2: Platform | C2: Date | D2: Content Type | E2: Post Text | F2: Likes | G2: Shares | H2: Comments | I2: Impressions | J2: Reach | K2: Clicks | L2: Hashtags Used | M2: Hashtags-1 | N2: Hashtags_2 | O2: Campaign_Name | P2: Engagement rate
A3: P001 | B3: Twitter | C3: 45649 | D3: Reel | E3: Check out our latest reel on twitter! | F3: 1461 | G3: 184 | H3: 344 | I3: 21915 | J3: 21675 | K3: 15 | L3: #FutureOfDriving | M3: #AnytimeIsTeslaTime | N3: no data | O3: CybertruckLaunch | P3: =(Table1_145[[#This Row],[Likes]]+Table1_145[[#This Row],[Shares]]+Table1_145[[#This Row],[Comments]])/Table1_145[[#This Row],[Impressions]] -> 0.090759754
A4: P002 | B4: Twitter | C4: 45750 | D4: Text | E4: Check out our latest text on twitter! | F4: 4054 | G4: 389 | H4: 493 | I4: 64864 | J4: 64383 | K4: 117 | L4: #TeslaCoInnovation | M4: #BetterWithTesla | N4: no data | O4: ModelYCampaign | P4: =(Table1_145[[#This Row],[Likes]]+Table1_145[[#This Row],[Shares]]+Table1_145[[#This Row],[Comments]])/Table1_145[[#This Row],[Impressions]] -> 0.076097681
A5: P003 | B5: YouTube | C5: 45789 | D5: Reel | E5: Check out our latest reel on youtube! | F5: 2795 | G5: 105 | H5: 49 | I5: 53105 | J5: 52307 | K5: 204 | L5: #TeslaCoInnovation | M5: no data | N5: no data | O5: FSDUpdate | P5: =(Table1_145[[#This Row],[Likes]]+Table1_145[[#This Row],[Shares]]+Table1_145[[#This Row],[Comments]])/Table1_145[[#This Row],[Impressions]] -> 0.055531494
A6: P004 | B6: Instagram | C6: 45516 | D6: Story | E6: Check out our latest story on instagram! | F6: 2404 | G6: 363 | H6: 138 | I6: 19232 | J6: 18636 | K6: 128 | L6: #EVRevolution | M6: no data | N6: no data | O6: SustainabilityDrive | P6: =(Table1_145[[#This Row],[Likes]]+Table1_145[[#This Row],[Shares]]+Table1_145[[#This Row],[Comments]])/Table1_145[[#This Row],[Impressions]] -> 0.15105033
A7: P005 | B7: YouTube | C7: 45469 | D7: Reel | E7: Check out our latest reel on youtube! | F7: 3557 | G7: 687 | H7: 424 | I7: 71140 | J7: 70701 | K7: 224 | L7: #EVRevolution | M7: #TeslaCoInnovation | N7: no data | O7: CybertruckLaunch | P7: =(Table1_145[[#This Row],[Likes]]+Table1_145[[#This Row],[Shares]]+Table1_145[[#This Row],[Comments]])/Table1_145[[#This Row],[Impressions]] -> 0.065617093
A8: P006 | B8: Facebook | C8: 45596 | D8: Carousel | E8: Check out our latest carousel on facebook! | F8: 2945 | G8: 930 | H8: 355 | I8: 23560 | J8: 23275 | K8: 256 | L8: #TeslaCoInnovation | M8: no data | N8: no data | O8: ModelYCampaign | P8: =(Table1_145[[#This Row],[Likes]]+Table1_145[[#This Row],[Shares]]+Table1_145[[#This Row],[Comments]])/Table1_145[[#This Row],[Impressions]] -> 0.1795416
A9: P007 | B9: Twitter | C9: 45467 | D9: Carousel | E9: Check out our latest carousel on twitter! | F9: 3860 | G9: 201 | H9: 279 | I9: 61760 | J9: 61660 | K9: 235 | L9: #TeslaCoInnovation | M9: no data | N9: no data | O9: ModelYCampaign | P9: =(Table1_145[[#This Row],[Likes]]+Table1_145[[#This Row],[Shares]]+Table1_145[[#This Row],[Comments]])/Table1_145[[#This Row],[Impressions]] -> 0.070272021
A10: P008 | B10: YouTube | C10: 45486 | D10: Image | E10: Check out our latest image on youtube! | F10: 3929 | G10: 262 | H10: 278 | I10: 43219 | J10: 42841 | K10: 39 | L10: #EVRevolution | M10: no data | N10: no data | O10: SustainabilityDrive | P10: =(Table1_145[[#This Row],[Likes]]+Table1_145[[#This Row],[Shares]]+Table1_145[[#This Row],[Comments]])/Table1_145[[#This Row],[Impressions]] -> 0.1034036
A11: P009 | B11: Facebook | C11: 45534 | D11: Text | E11: Check out our latest text on facebook! | F11: 3784 | G11: 808 | H11: 404 | I11: 56760 | J11: 56343 | K11: 131 | L11: #TeslaCoInnovation | M11: no data | N11: no data | O11: ModelYCampaign | P11: =(Table1_145[[#This Row],[Likes]]+Table1_145[[#This Row],[Shares]]+Table1_145[[#This Row],[Comments]])/Table1_145[[#This Row],[Impressions]] -> 0.088019732
A12: P010 | B12: Facebook | C12: 45727 | D12: Image | E12: Check out our latest image on facebook! | F12: 4241 | G12: 902 | H12: 47 | I12: 72097 | J12: 71598 | K12: 167 | L12: #TeslaCoInnovation | M12: no data | N12: no data | O12: ModelYCampaign | P12: =(Table1_145[[#This Row],[Likes]]+Table1_145[[#This Row],[Shares]]+Table1_145[[#This Row],[Comments]])/Table1_145[[#This Row],[Impressions]] -> 0.071986352
A13: P011 | B13: Instagram | C13: 45690 | D13: Story | E13: Check out our latest story on instagram! | F13: 1792 | G13: 614 | H13: 497 | I13: 25088 | J13: 24675 | K13: 65 | L13: #FutureOfDriving | M13: no data | N13: no data | O13: SustainabilityDrive | P13: =(Table1_145[[#This Row],[Likes]]+Table1_145[[#This Row],[Shares]]+Table1_145[[#This Row],[Comments]])/Table1_145[[#This Row],[Impressions]] -> 0.11571269
A14: P012 | B14: Facebook | C14: 45494 | D14: Reel | E14: Check out our latest reel on facebook! | F14: 1946 | G14: 686 | H14: 377 | I14: 23352 | J14: 22982 | K14: 213 | L14: #FutureOfDriving | M14: no data | N14: no data | O14: FSDUpdate | P14: =(Table1_145[[#This Row],[Likes]]+Table1_145[[#This Row],[Shares]]+Table1_145[[#This Row],[Comments]])/Table1_145[[#This Row],[Impressions]] -> 0.12885406
... A302: P300 | B302: Twitter | C302: 45535 | D302: Carousel | E302: Check out our latest carousel on twitter! | F302: 4494 | G302: 717 | H302: 45 | I302: 62916 | J302: 62688 | K302: 191 | L302: #TeslaCoInnovation | M302: #EVRevolution | N302: #BetterWithTesla | O302: CybertruckLaunch | P302: =(Table1_145[[#This Row],[Likes]]+Table1_145[[#This Row],[Shares]]+Table1_145[[#This Row],[Comments]])/Table1_145[[#This Row],[Impressions]] -> 0.083539958

Sheet Task_2.3(1)
D3: TOTAL LIKES, SHARES, COMMENTS BY CONTENT TYPE AND PLATFORM
B7: Column Labels
B8: Facebook | E8: Instagram | H8: Twitter | K8: YouTube
A9: Row Labels | B9: Sum of Likes | C9: Sum of Shares | D9: Sum of Comments | E9: Sum of Likes | F9: Sum of Shares | G9: Sum of Comments | H9: Sum of Likes | I9: Sum of Shares | J9: Sum of Comments | K9: Sum of Likes | L9: Sum of Shares | M9: Sum of Comments
A10: Carousel | B10: 44476 | C10: 7400 | D10: 4589 | E10: 43948 | F10: 6975 | G10: 3890 | H10: 48649 | I10: 5791 | J10: 3607 | K10: 24926 | L10: 6305 | M10: 2422
A11: Story | B11: 29405 | C11: 4950 | D11: 3223 | E11: 42649 | F11: 10049 | G11: 3846 | H11: 20466 | I11: 5090 | J11: 3026 | K11: 31968 | L11: 3866 | M11: 2012
A12: Text | B12: 31963 | C12: 4792 | D12: 3377 | E12: 25567 | F12: 5112 | G12: 1946 | H12: 31899 | I12: 4861 | J12: 3910 | K12: 27067 | L12: 3928 | M12: 1052
A13: Video | B13: 28947 | C13: 3171 | D13: 2263 | E13: 25770 | F13: 5912 | G13: 2128 | H13: 29593 | I13: 6326 | J13: 3299 | K13: 31285 | L13: 5586 | M13: 2589

Sheet Task_2.3(2)
D6: AVERAGE CLICKS PER POSTS BY HASHTAGS
B14: Row Labels | C14: Average of Clicks
B15: #AnytimeIsTeslaTime | C15: 161.2
B16: #TeslaCoInnovation | C16: 158.65421
B17: #EVRevolution | C17: 151.52941
B18: #FutureOfDriving | C18: 144.03883
B19: #BetterWithTesla | C19: 114.85714
B20: #SmoothLikeNitroTesla | C20: 111.8
B21: Grand Total | C21: 150.58702

Sheet Unpivoted_columns
A1: Post ID | B1: Platform | C1: Date | D1: Content Type | E1: Post Text | F1: Likes | G1: Shares | H1: Comments | I1: Impressions | J1: Reach | K1: Clicks | L1: Campaign_Name | M1: Attribute | N1: Hashtags
A2: P001 | B2: Twitter | C2: 45649 | D2: Reel | E2: Check out our latest reel on twitter! | F2: 1461 | G2: 184 | H2: 344 | I2: 21915 | J2: 21675 | K2: 15 | L2: CybertruckLaunch | M2: Hashtags Used | N2: #FutureOfDriving
A3: P001 | B3: Twitter | C3: 45649 | D3: Reel | E3: Check out our latest reel on twitter! | F3: 1461 | G3: 184 | H3: 344 | I3: 21915 | J3: 21675 | K3: 15 | L3: CybertruckLaunch | M3: Hashtags-1 | N3: #AnytimeIsTeslaTime
A4: P001 | B4: Twitter | C4: 45649 | D4: Reel | E4: Check out our latest reel on twitter! | F4: 1461 | G4: 184 | H4: 344 | I4: 21915 | J4: 21675 | K4: 15 | L4: CybertruckLaunch | M4: Hashtags_2 | N4: no data
A5: P002 | B5: Twitter | C5: 45750 | D5: Text | E5: Check out our latest text on twitter! | F5: 4054 | G5: 389 | H5: 493 | I5: 64864 | J5: 64383 | K5: 117 | L5: ModelYCampaign | M5: Hashtags Used | N5: #TeslaCoInnovation
A6: P002 | B6: Twitter | C6: 45750 | D6: Text | E6: Check out our latest text on twitter! | F6: 4054 | G6: 389 | H6: 493 | I6: 64864 | J6: 64383 | K6: 117 | L6: ModelYCampaign | M6: Hashtags-1 | N6: #BetterWithTesla
A7: P002 | B7: Twitter | C7: 45750 | D7: Text | E7: Check out our latest text on twitter! | F7: 4054 | G7: 389 | H7: 493 | I7: 64864 | J7: 64383 | K7: 117 | L7: ModelYCampaign | M7: Hashtags_2 | N7: no data
A8: P003 | B8: YouTube | C8: 45789 | D8: Reel | E8: Check out our latest reel on youtube! | F8: 2795 | G8: 105 | H8: 49 | I8: 53105 | J8: 52307 | K8: 204 | L8: FSDUpdate | M8: Hashtags Used | N8: #TeslaCoInnovation
A9: P003 | B9: YouTube | C9: 45789 | D9: Reel | E9: Check out our latest reel on youtube! | F9: 2795 | G9: 105 | H9: 49 | I9: 53105 | J9: 52307 | K9: 204 | L9: FSDUpdate | M9: Hashtags-1 | N9: no data
A10: P003 | B10: YouTube | C10: 45789 | D10: Reel | E10: Check out our latest reel on youtube! | F10: 2795 | G10: 105 | H10: 49 | I10: 53105 | J10: 52307 | K10: 204 | L10: FSDUpdate | M10: Hashtags_2 | N10: no data
A11: P004 | B11: Instagram | C11: 45516 | D11: Story | E11: Check out our latest story on instagram! | F11: 2404 | G11: 363 | H11: 138 | I11: 19232 | J11: 18636 | K11: 128 | L11: SustainabilityDrive | M11: Hashtags Used | N11: #EVRevolution
A12: P004 | B12: Instagram | C12: 45516 | D12: Story | E12: Check out our latest story on instagram! | F12: 2404 | G12: 363 | H12: 138 | I12: 19232 | J12: 18636 | K12: 128 | L12: SustainabilityDrive | M12: Hashtags-1 | N12: no data
A13: P004 | B13: Instagram | C13: 45516 | D13: Story | E13: Check out our latest story on instagram! | F13: 2404 | G13: 363 | H13: 138 | I13: 19232 | J13: 18636 | K13: 128 | L13: SustainabilityDrive | M13: Hashtags_2 | N13: no data
... A901: P300 | B901: Twitter | C901: 45535 | D901: Carousel | E901: Check out our latest carousel on twitter! | F901: 4494 | G901: 717 | H901: 45 | I901: 62916 | J901: 62688 | K901: 191 | L901: CybertruckLaunch | M901: Hashtags_2 | N901: #BetterWithTesla

Sheet Task_2.4
E3: Top performing Hashtags
C12: Row Labels | D12: Average of Clicks
C13: #AnytimeIsTeslaTime | D13: 161.2
C14: #TeslaCoInnovation | D14: 158.65421
C15: #EVRevolution | D15: 151.52941
C16: #FutureOfDriving | D16: 144.03883
C17: #BetterWithTesla | D17: 114.85714
C18: #SmoothLikeNitroTesla | D18: 111.8
C19: Grand Total | D19: 150.58702
D25: #AnytimelsTeslaTime,#TeslaColnnovation are top performing Hashtags

Sheet Task_3.1
A1: Post ID | B1: Platform | C1: Date | D1: Content Type | E1: Post Text | F1: Likes | G1: Shares | H1: Comments | I1: Impressions | J1: Reach | K1: Clicks | L1: Hashtags Used | M1: Hashtags-1 | N1: Hashtags_2 | O1: Campaign_Name | P1: Engagement rate | Q1: Total_Engagement
A2: P001 | B2: Twitter | C2: 45649 | D2: Reel | E2: Check out our latest reel on twitter! | F2: 1461 | G2: 184 | H2: 344 | I2: 21915 | J2: 21675 | K2: 15 | L2: #FutureOfDriving | M2: #AnytimeIsTeslaTime | N2: no data | O2: CybertruckLaunch | P2: =(Table1_147[[#This Row],[Likes]]+Table1_147[[#This Row],[Shares]]+Table1_147[[#This Row],[Comments]])/Table1_147[[#This Row],[Impressions]] -> 0.090759754 | Q2: =(Table1_147[[#This Row],[Likes]]+Table1_147[[#This Row],[Shares]]+Table1_147[[#This Row],[Comments]]) -> 1989
A3: P002 | B3: Twitter | C3: 45750 | D3: Text | E3: Check out our latest text on twitter! | F3: 4054 | G3: 389 | H3: 493 | I3: 64864 | J3: 64383 | K3: 117 | L3: #TeslaCoInnovation | M3: #BetterWithTesla | N3: no data | O3: ModelYCampaign | P3: =(Table1_147[[#This Row],[Likes]]+Table1_147[[#This Row],[Shares]]+Table1_147[[#This Row],[Comments]])/Table1_147[[#This Row],[Impressions]] -> 0.076097681 | Q3: =(Table1_147[[#This Row],[Likes]]+Table1_147[[#This Row],[Shares]]+Table1_147[[#This Row],[Comments]]) -> 4936
A4: P003 | B4: YouTube | C4: 45789 | D4: Reel | E4: Check out our latest reel on youtube! | F4: 2795 | G4: 105 | H4: 49 | I4: 53105 | J4: 52307 | K4: 204 | L4: #TeslaCoInnovation | M4: no data | N4: no data | O4: FSDUpdate | P4: =(Table1_147[[#This Row],[Likes]]+Table1_147[[#This Row],[Shares]]+Table1_147[[#This Row],[Comments]])/Table1_147[[#This Row],[Impressions]] -> 0.055531494 | Q4: =(Table1_147[[#This Row],[Likes]]+Table1_147[[#This Row],[Shares]]+Table1_147[[#This Row],[Comments]]) -> 2949
A5: P004 | B5: Instagram | C5: 45516 | D5: Story | E5: Check out our latest story on instagram! | F5: 2404 | G5: 363 | H5: 138 | I5: 19232 | J5: 18636 | K5: 128 | L5: #EVRevolution | M5: no data | N5: no data | O5: SustainabilityDrive | P5: =(Table1_147[[#This Row],[Likes]]+Table1_147[[#This Row],[Shares]]+Table1_147[[#This Row],[Comments]])/Table1_147[[#This Row],[Impressions]] -> 0.15105033 | Q5: =(Table1_147[[#This Row],[Likes]]+Table1_147[[#This Row],[Shares]]+Table1_147[[#This Row],[Comments]]) -> 2905 | T5: Platform with highest engagement is Facebook
A6: P005 | B6: YouTube | C6: 45469 | D6: Reel | E6: Check out our latest reel on youtube! | F6: 3557 | G6: 687 | H6: 424 | I6: 71140 | J6: 70701 | K6: 224 | L6: #EVRevolution | M6: #TeslaCoInnovation | N6: no data | O6: CybertruckLaunch | P6: =(Table1_147[[#This Row],[Likes]]+Table1_147[[#This Row],[Shares]]+Table1_147[[#This Row],[Comments]])/Table1_147[[#This Row],[Impressions]] -> 0.065617093 | Q6: =(Table1_147[[#This Row],[Likes]]+Table1_147[[#This Row],[Shares]]+Table1_147[[#This Row],[Comments]]) -> 4668
A7: P006 | B7: Facebook | C7: 45596 | D7: Carousel | E7: Check out our latest carousel on facebook! | F7: 2945 | G7: 930 | H7: 355 | I7: 23560 | J7: 23275 | K7: 256 | L7: #TeslaCoInnovation | M7: no data | N7: no data | O7: ModelYCampaign | P7: =(Table1_147[[#This Row],[Likes]]+Table1_147[[#This Row],[Shares]]+Table1_147[[#This Row],[Comments]])/Table1_147[[#This Row],[Impressions]] -> 0.1795416 | Q7: =(Table1_147[[#This Row],[Likes]]+Table1_147[[#This Row],[Shares]]+Table1_147[[#This Row],[Comments]]) -> 4230
A8: P007 | B8: Twitter | C8: 45467 | D8: Carousel | E8: Check out our latest carousel on twitter! | F8: 3860 | G8: 201 | H8: 279 | I8: 61760 | J8: 61660 | K8: 235 | L8: #TeslaCoInnovation | M8: no data | N8: no data | O8: ModelYCampaign | P8: =(Table1_147[[#This Row],[Likes]]+Table1_147[[#This Row],[Shares]]+Table1_147[[#This Row],[Comments]])/Table1_147[[#This Row],[Impressions]] -> 0.070272021 | Q8: =(Table1_147[[#This Row],[Likes]]+Table1_147[[#This Row],[Shares]]+Table1_147[[#This Row],[Comments]]) -> 4340 | T8: Row Labels | U8: Sum of Total_Engagement
A9: P008 | B9: YouTube | C9: 45486 | D9: Image | E9: Check out our latest image on youtube! | F9: 3929 | G9: 262 | H9: 278 | I9: 43219 | J9: 42841 | K9: 39 | L9: #EVRevolution | M9: no data | N9: no data | O9: SustainabilityDrive | P9: =(Table1_147[[#This Row],[Likes]]+Table1_147[[#This Row],[Shares]]+Table1_147[[#This Row],[Comments]])/Table1_147[[#This Row],[Impressions]] -> 0.1034036 | Q9: =(Table1_147[[#This Row],[Likes]]+Table1_147[[#This Row],[Shares]]+Table1_147[[#This Row],[Comments]]) -> 4469 | T9: Facebook | U9: 305242
A10: P009 | B10: Facebook | C10: 45534 | D10: Text | E10: Check out our latest text on facebook! | F10: 3784 | G10: 808 | H10: 404 | I10: 56760 | J10: 56343 | K10: 131 | L10: #TeslaCoInnovation | M10: no data | N10: no data | O10: ModelYCampaign | P10: =(Table1_147[[#This Row],[Likes]]+Table1_147[[#This Row],[Shares]]+Table1_147[[#This Row],[Comments]])/Table1_147[[#This Row],[Impressions]] -> 0.088019732 | Q10: =(Table1_147[[#This Row],[Likes]]+Table1_147[[#This Row],[Shares]]+Table1_147[[#This Row],[Comments]]) -> 4996 | T10: Instagram | U10: 263579
A11: P010 | B11: Facebook | C11: 45727 | D11: Image | E11: Check out our latest image on facebook! | F11: 4241 | G11: 902 | H11: 47 | I11: 72097 | J11: 71598 | K11: 167 | L11: #TeslaCoInnovation | M11: no data | N11: no data | O11: ModelYCampaign | P11: =(Table1_147[[#This Row],[Likes]]+Table1_147[[#This Row],[Shares]]+Table1_147[[#This Row],[Comments]])/Table1_147[[#This Row],[Impressions]] -> 0.071986352 | Q11: =(Table1_147[[#This Row],[Likes]]+Table1_147[[#This Row],[Shares]]+Table1_147[[#This Row],[Comments]]) -> 5190 | T11: Twitter | U11: 256005
A12: P011 | B12: Instagram | C12: 45690 | D12: Story | E12: Check out our latest story on instagram! | F12: 1792 | G12: 614 | H12: 497 | I12: 25088 | J12: 24675 | K12: 65 | L12: #FutureOfDriving | M12: no data | N12: no data | O12: SustainabilityDrive | P12: =(Table1_147[[#This Row],[Likes]]+Table1_147[[#This Row],[Shares]]+Table1_147[[#This Row],[Comments]])/Table1_147[[#This Row],[Impressions]] -> 0.11571269 | Q12: =(Table1_147[[#This Row],[Likes]]+Table1_147[[#This Row],[Shares]]+Table1_147[[#This Row],[Comments]]) -> 2903 | T12: YouTube | U12: 212941
A13: P012 | B13: Facebook | C13: 45494 | D13: Reel | E13: Check out our latest reel on facebook! | F13: 1946 | G13: 686 | H13: 377 | I13: 23352 | J13: 22982 | K13: 213 | L13: #FutureOfDriving | M13: no data | N13: no data | O13: FSDUpdate | P13: =(Table1_147[[#This Row],[Likes]]+Table1_147[[#This Row],[Shares]]+Table1_147[[#This Row],[Comments]])/Table1_147[[#This Row],[Impressions]] -> 0.12885406 | Q13: =(Table1_147[[#This Row],[Likes]]+Table1_147[[#This Row],[Shares]]+Table1_147[[#This Row],[Comments]]) -> 3009 | T13: Grand Total | U13: 1037767
A14: P013 | B14: YouTube | C14: 45614 | D14: Carousel | E14: Check out our latest carousel on youtube! | F14: 1171 | G14: 286 | H14: 231 | I14: 22249 | J14: 21282 | K14: 114 | L14: #EVRevolution | M14: no data | N14: no data | O14: CybertruckLaunch | P14: =(Table1_147[[#This Row],[Likes]]+Table1_147[[#This Row],[Shares]]+Table1_147[[#This Row],[Comments]])/Table1_147[[#This Row],[Impressions]] -> 0.075868578 | Q14: =(Table1_147[[#This Row],[Likes]]+Table1_147[[#This Row],[Shares]]+Table1_147[[#This Row],[Comments]]) -> 1688
A15: P014 | B15: Facebook | C15: 45704 | D15: Story | E15: Check out our latest story on facebook! | F15: 4242 | G15: 555 | H15: 131 | I15: 33936 | J15: 33802 | K15: 265 | L15: #FutureOfDriving | M15: no data | N15: no data | O15: unknown | P15: =(Table1_147[[#This Row],[Likes]]+Table1_147[[#This Row],[Shares]]+Table1_147[[#This Row],[Comments]])/Table1_147[[#This Row],[Impressions]] -> 0.14521452 | Q15: =(Table1_147[[#This Row],[Likes]]+Table1_147[[#This Row],[Shares]]+Table1_147[[#This Row],[Comments]]) -> 4928
A16: P015 | B16: Facebook | C16: 45589 | D16: Video | E16: Check out our latest video on facebook! | F16: 3888 | G16: 604 | H16: 128 | I16: 77760 | J16: 77167 | K16: 20 | L16: #FutureOfDriving | M16: no data | N16: no data | O16: CybertruckLaunch | P16: =(Table1_147[[#This Row],[Likes]]+Table1_147[[#This Row],[Shares]]+Table1_147[[#This Row],[Comments]])/Table1_147[[#This Row],[Impressions]] -> 0.05941358 | Q16: =(Table1_147[[#This Row],[Likes]]+Table1_147[[#This Row],[Shares]]+Table1_147[[#This Row],[Comments]]) -> 4620
A17: P016 | B17: Facebook | C17: 45530 | D17: Text | E17: Check out our latest text on facebook! | F17: 3452 | G17: 377 | H17: 360 | I17: 55232 | J17: 55075 | K17: 87 | L17: #FutureOfDriving | M17: no data | N17: no data | O17: FSDUpdate | P17: =(Table1_147[[#This Row],[Likes]]+Table1_147[[#This Row],[Shares]]+Table1_147[[#This Row],[Comments]])/Table1_147[[#This Row],[Impressions]] -> 0.075843714 | Q17: =(Table1_147[[#This Row],[Likes]]+Table1_147[[#This Row],[Shares]]+Table1_147[[#This Row],[Comments]]) -> 4189
A18: P017 | B18: Facebook | C18: 45782 | D18: Text | E18: Check out our latest text on facebook! | F18: 4441 | G18: 511 | H18: 70 | I18: 53292 | J18: 53082 | K18: 159 | L18: #EVRevolution | M18: no data | N18: no data | O18: SustainabilityDrive | P18: =(Table1_147[[#This Row],[Likes]]+Table1_147[[#This Row],[Shares]]+Table1_147[[#This Row],[Comments]])/Table1_147[[#This Row],[Impressions]] -> 0.094235533 | Q18: =(Table1_147[[#This Row],[Likes]]+Table1_147[[#This Row],[Shares]]+Table1_147[[#This Row],[Comments]]) -> 5022
A19: P018 | B19: Instagram | C19: 45523 | D19: Reel | E19: Check out our latest reel on instagram! | F19: 3000 | G19: 382 | H19: 325 | I19: 36000 | J19: 35819 | K19: 19 | L19: #FutureOfDriving | M19: no data | N19: no data | O19: CybertruckLaunch | P19: =(Table1_147[[#This Row],[Likes]]+Table1_147[[#This Row],[Shares]]+Table1_147[[#This Row],[Comments]])/Table1_147[[#This Row],[Impressions]] -> 0.10297222 | Q19: =(Table1_147[[#This Row],[Likes]]+Table1_147[[#This Row],[Shares]]+Table1_147[[#This Row],[Comments]]) -> 3707
A20: P019 | B20: Instagram | C20: 45466 | D20: Video | E20: Check out our latest video on instagram! | F20: 1071 | G20: 519 | H20: 22 | I20: 16065 | J20: 15865 | K20: 103 | L20: #TeslaCoInnovation | M20: no data | N20: no data | O20: SustainabilityDrive | P20: =(Table1_147[[#This Row],[Likes]]+Table1_147[[#This Row],[Shares]]+Table1_147[[#This Row],[Comments]])/Table1_147[[#This Row],[Impressions]] -> 0.10034236 | Q20: =(Table1_147[[#This Row],[Likes]]+Table1_147[[#This Row],[Shares]]+Table1_147[[#This Row],[Comments]]) -> 1612
A21: P020 | B21: Instagram | C21: 45544 | D21: Carousel | E21: Check out our latest carousel on instagram! | F21: 4054 | G21: 488 | H21: 373 | I21: 77026 | J21: 76881 | K21: 25 | L21: #TeslaCoInnovation | M21: no data | N21: no data | O21: CybertruckLaunch | P21: =(Table1_147[[#This Row],[Likes]]+Table1_147[[#This Row],[Shares]]+Table1_147[[#This Row],[Comments]])/Table1_147[[#This Row],[Impressions]] -> 0.063809623 | Q21: =(Table1_147[[#This Row],[Likes]]+Table1_147[[#This Row],[Shares]]+Table1_147[[#This Row],[Comments]]) -> 4915
A22: P021 | B22: Instagram | C22: 45661 | D22: Reel | E22: Check out our latest reel on instagram! | F22: 4838 | G22: 640 | H22: 128 | I22: 72570 | J22: 72396 | K22: 83 | L22: #FutureOfDriving | M22: no data | N22: no data | O22: SustainabilityDrive | P22: =(Table1_147[[#This Row],[Likes]]+Table1_147[[#This Row],[Shares]]+Table1_147[[#This Row],[Comments]])/Table1_147[[#This Row],[Impressions]] -> 0.077249552 | Q22: =(Table1_147[[#This Row],[Likes]]+Table1_147[[#This Row],[Shares]]+Table1_147[[#This Row],[Comments]]) -> 5606
A23: P022 | B23: Facebook | C23: 45715 | D23: Text | E23: Check out our latest text on facebook! | F23: 1570 | G23: 187 | H23: 260 | I23: 25120 | J23: 24613 | K23: 133 | L23: #TeslaCoInnovation | M23: no data | N23: no data | O23: SustainabilityDrive | P23: =(Table1_147[[#This Row],[Likes]]+Table1_147[[#This Row],[Shares]]+Table1_147[[#This Row],[Comments]])/Table1_147[[#This Row],[Impressions]] -> 0.080294586 | Q23: =(Table1_147[[#This Row],[Likes]]+Table1_147[[#This Row],[Shares]]+Table1_147[[#This Row],[Comments]]) -> 2017
A24: P023 | B24: Facebook | C24: 45602 | D24: Video | E24: Check out our latest video on facebook! | F24: 1606 | G24: 547 | H24: 316 | I24: 32120 | J24: 31736 | K24: 225 | L24: #TeslaCoInnovation | M24: #AnytimeIsTeslaTime | N24: no data | O24: ModelYCampaign | P24: =(Table1_147[[#This Row],[Likes]]+Table1_147[[#This Row],[Shares]]+Table1_147[[#This Row],[Comments]])/Table1_147[[#This Row],[Impressions]] -> 0.076867995 | Q24: =(Table1_147[[#This Row],[Likes]]+Table1_147[[#This Row],[Shares]]+Table1_147[[#This Row],[Comments]]) -> 2469
A25: P024 | B25: Facebook | C25: 45680 | D25: Video | E25: Check out our latest video on facebook! | F25: 3961 | G25: 761 | H25: 131 | I25: 67337 | J25: 66615 | K25: 161 | L25: #FutureOfDriving | M25: no data | N25: no data | O25: FSDUpdate | P25: =(Table1_147[[#This Row],[Likes]]+Table1_147[[#This Row],[Shares]]+Table1_147[[#This Row],[Comments]])/Table1_147[[#This Row],[Impressions]] -> 0.072070333 | Q25: =(Table1_147[[#This Row],[Likes]]+Table1_147[[#This Row],[Shares]]+Table1_147[[#This Row],[Comments]]) -> 4853
... A301: P300 | B301: Twitter | C301: 45535 | D301: Carousel | E301: Check out our latest carousel on twitter! | F301: 4494 | G301: 717 | H301: 45 | I301: 62916 | J301: 62688 | K301: 191 | L301: #TeslaCoInnovation | M301: #EVRevolution | N301: #BetterWithTesla | O301: CybertruckLaunch | P301: =(Table1_147[[#This Row],[Likes]]+Table1_147[[#This Row],[Shares]]+Table1_147[[#This Row],[Comments]])/Table1_147[[#This Row],[Impressions]] -> 0.083539958 | Q301: =(Table1_147[[#This Row],[Likes]]+Table1_147[[#This Row],[Shares]]+Table1_147[[#This Row],[Comments]]) -> 5256

Sheet Engagement summary
A1: Week_Start_Date | B1: Platform | C1: New_Followers | D1: Unfollows | E1: Total_Followers | F1: Engagement_Rate | G1: Ad_Spend | H1: Net Followers | I1: Growth rate | J1: Campaign_Name
A2: 2024-06-03 | B2: Instagram | C2: 1135 | D2: 88 | E2: 344084 | F2: 8.06 | G2: 5904 | H2: =C2-D2 -> 1047 | I2: =H2/E2 -> 0.0030428616 | J2: {=IFERROR( INDEX(Posts!$O:$O, MATCH(1, (TRIM(UPPER(Posts!$B:$B))=TRIM(UPPER(B2)))* (ABS(Posts!$C:$C - A2) <= 7), 0)), "unknown")} -> SustainabilityDrive
A3: 2024-06-03 | B3: Facebook | C3: 1312 | D3: 310 | E3: 42654 | F3: 4.98 | G3: 9566 | H3: =C3-D3 -> 1002 | I3: =H3/E3 -> 0.023491349 | J3: {=IFERROR( INDEX(Posts!$O:$O, MATCH(1, (TRIM(UPPER(Posts!$B:$B))=TRIM(UPPER(B3)))* (ABS(Posts!$C:$C - A3) <= 7), 0)), "unknown")} -> FSDUpdate
A4: 2024-06-03 | B4: Twitter | C4: 584 | D4: 169 | E4: 146834 | F4: 8.31 | G4: 26752 | H4: =C4-D4 -> 415 | I4: =H4/E4 -> 0.0028263209 | J4: {=IFERROR( INDEX(Posts!$O:$O, MATCH(1, (TRIM(UPPER(Posts!$B:$B))=TRIM(UPPER(B4)))* (ABS(Posts!$C:$C - A4) <= 7), 0)), "unknown")} -> SustainabilityDrive
A5: 2024-06-03 | B5: YouTube | C5: 1535 | D5: 445 | E5: 395536 | F5: 4.11 | G5: 30671 | H5: =C5-D5 -> 1090 | I5: =H5/E5 -> 0.0027557542 | J5: {=IFERROR( INDEX(Posts!$O:$O, MATCH(1, (TRIM(UPPER(Posts!$B:$B))=TRIM(UPPER(B5)))* (ABS(Posts!$C:$C - A5) <= 7), 0)), "unknown")} -> unknown
A6: 2024-06-10 | B6: Instagram | C6: 656 | D6: 139 | E6: 49157 | F6: 9.05 | G6: 9920 | H6: =C6-D6 -> 517 | I6: =H6/E6 -> 0.010517322 | J6: {=IFERROR( INDEX(Posts!$O:$O, MATCH(1, (TRIM(UPPER(Posts!$B:$B))=TRIM(UPPER(B6)))* (ABS(Posts!$C:$C - A6) <= 7), 0)), "unknown")} -> unknown
A7: 2024-06-10 | B7: Facebook | C7: 1697 | D7: 414 | E7: 316555 | F7: 2.37 | G7: 7924 | H7: =C7-D7 -> 1283 | I7: =H7/E7 -> 0.0040530082 | J7: {=IFERROR( INDEX(Posts!$O:$O, MATCH(1, (TRIM(UPPER(Posts!$B:$B))=TRIM(UPPER(B7)))* (ABS(Posts!$C:$C - A7) <= 7), 0)), "unknown")} -> ModelYCampaign
A8: 2024-06-10 | B8: Twitter | C8: 436 | D8: 250 | E8: 254347 | F8: 4.01 | G8: 8912 | H8: =C8-D8 -> 186 | I8: =H8/E8 -> 0.00073128443 | J8: {=IFERROR( INDEX(Posts!$O:$O, MATCH(1, (TRIM(UPPER(Posts!$B:$B))=TRIM(UPPER(B8)))* (ABS(Posts!$C:$C - A8) <= 7), 0)), "unknown")} -> SustainabilityDrive
A9: 2024-06-10 | B9: YouTube | C9: 1197 | D9: 203 | E9: 413878 | F9: 3.16 | G9: 21205 | H9: =C9-D9 -> 994 | I9: =H9/E9 -> 0.0024016739 | J9: {=IFERROR( INDEX(Posts!$O:$O, MATCH(1, (TRIM(UPPER(Posts!$B:$B))=TRIM(UPPER(B9)))* (ABS(Posts!$C:$C - A9) <= 7), 0)), "unknown")} -> unknown
A10: 2024-06-17 | B10: Instagram | C10: 1048 | D10: 155 | E10: 456946 | F10: 2.46 | G10: 11329 | H10: =C10-D10 -> 893 | I10: =H10/E10 -> 0.0019542791 | J10: {=IFERROR( INDEX(Posts!$O:$O, MATCH(1, (TRIM(UPPER(Posts!$B:$B))=TRIM(UPPER(B10)))* (ABS(Posts!$C:$C - A10) <= 7), 0)), "unknown")} -> SustainabilityDrive
A11: 2024-06-17 | B11: Facebook | C11: 1753 | D11: 371 | E11: 169496 | F11: 8.11 | G11: 46670 | H11: =C11-D11 -> 1382 | I11: =H11/E11 -> 0.0081535847 | J11: {=IFERROR( INDEX(Posts!$O:$O, MATCH(1, (TRIM(UPPER(Posts!$B:$B))=TRIM(UPPER(B11)))* (ABS(Posts!$C:$C - A11) <= 7), 0)), "unknown")} -> ModelYCampaign
A12: 2024-06-17 | B12: Twitter | C12: 1335 | D12: 40 | E12: 122732 | F12: 8.19 | G12: 22482 | H12: =C12-D12 -> 1295 | I12: =H12/E12 -> 0.010551445 | J12: {=IFERROR( INDEX(Posts!$O:$O, MATCH(1, (TRIM(UPPER(Posts!$B:$B))=TRIM(UPPER(B12)))* (ABS(Posts!$C:$C - A12) <= 7), 0)), "unknown")} -> ModelYCampaign
A13: 2024-06-17 | B13: YouTube | C13: 403 | D13: 66 | E13: 382851 | F13: 3.49 | G13: 24313 | H13: =C13-D13 -> 337 | I13: =H13/E13 -> 0.000880238 | J13: {=IFERROR( INDEX(Posts!$O:$O, MATCH(1, (TRIM(UPPER(Posts!$B:$B))=TRIM(UPPER(B13)))* (ABS(Posts!$C:$C - A13) <= 7), 0)), "unknown")} -> unknown
... A201: 2025-05-12 | B201: YouTube | C201: 119 | D201: 456 | E201: 82558 | F201: 6.81 | G201: 12174 | H201: =C201-D201 -> -337 | I201: =H201/E201 -> -0.0040819787 | J201: {=IFERROR( INDEX(Posts!$O:$O, MATCH(1, (TRIM(UPPER(Posts!$B:$B))=TRIM(UPPER(B201)))* (ABS(Posts!$C:$C - A201) <= 7), 0)), "unknown")} -> FSDUpdate

Sheet Task_3.2
D3: Follower Growth comparision across platforms
C12: Row Labels | D12: Average percentage of Growth rate
C13: Twitter | D13: 0.0092800257
C14: YouTube | D14: 0.0090210666
C15: Instagram | D15: 0.0057625321
C16: Facebook | D16: 0.0054649907
B20: Twitter shows the highest follower growth rate, and then Youtube, indicating these are the
B21: fastest-growing platform for Tesla's social media presence.

Sheet Task_3.3
E4: Ad Spend Vs Engagement Rate by Platform
C11: Row Labels | D11: Sum of Ad_Spend | E11: Average of Engagement_Rate
C12: Facebook | D12: 1379539 | E12: 5.6486
C13: Instagram | D13: 1164373 | E13: 5.7156
C14: Twitter | D14: 1060357 | E14: 5.6558
C15: YouTube | D15: 1228647 | E15: 5.5588
B18: Although Facebook had the highest ad spend, Instagram delivered higher engagement rates, suggesting
B19: better ROI(Return on Investment) for ads on Instagram.

Sheet Task_3.4
A2: Based on the analysis across engagement, follower growth, and ad performance, Tesla should maintain a multi-platform stratergy while using Twitter and YouTube for specialized content.
A3: * From Task_3.2, Twitter and Youtube have shown the highest follower growth rates, it means these are the effective platforms for Product launches, demos, and real-time updates.
A4: * From Task_3.1 and Task_3.3, Facebook and Instagram consistently generate higher engagement and better ROI(Return of Investment), making them crucial for brand storytelling, community engagement, and audience retention.
A5: * So, from the above data Tesla should continue investing across all platforms. This multi-platform approach ensures Tesla reaches a diverse audience, this way it can maximize visibility, engagement, and return on ad investment.
G8: Strategic Recommendation
G10: Platform | H10: Role
G11: Twitter | H11: Real-time news, product announcements
G12: Youtube | H12: Demos, launches, long-form content
G13: Instagram | H13: Visual campaigns, audience interaction
G14: Facebook | H14: Community engagement, broad reach

Sheet Task_4.1
C5: SustainabilityDrive campaign generated the highest engagement rate across platforms, showing strong audience interest in Tesla’s new product announcement.
C13: Row Labels | D13: Average of Engagement rate
C14: SustainabilityDrive | D14: 0.15203856
C15: FSDUpdate | D15: 0.14399919
C16: ModelYCampaign | D16: 0.14125279
C17: CybertruckLaunch | D17: 0.12925934

Sheet Table1
A1: Post ID | B1: Platform | C1: Date | D1: Content Type | E1: Post Text | F1: Likes | G1: Shares | H1: Comments | I1: Impressions | J1: Reach | K1: Clicks | L1: Campaign_Name | M1: Engagement rate | N1: Attribute | O1: Hashtags
A2: P001 | B2: Twitter | C2: 45649 | D2: Reel | E2: Check out our latest reel on twitter! | F2: 1461 | G2: 184 | H2: 344 | I2: 21915 | J2: 21675 | K2: 15 | L2: CybertruckLaunch | M2: 0.090759754 | N2: Hashtags Used | O2: #FutureOfDriving
A3: P001 | B3: Twitter | C3: 45649 | D3: Reel | E3: Check out our latest reel on twitter! | F3: 1461 | G3: 184 | H3: 344 | I3: 21915 | J3: 21675 | K3: 15 | L3: CybertruckLaunch | M3: 0.090759754 | N3: Hashtags-1 | O3: #AnytimeIsTeslaTime
A4: P001 | B4: Twitter | C4: 45649 | D4: Reel | E4: Check out our latest reel on twitter! | F4: 1461 | G4: 184 | H4: 344 | I4: 21915 | J4: 21675 | K4: 15 | L4: CybertruckLaunch | M4: 0.090759754 | N4: Hashtags_2 | O4: no data
A5: P002 | B5: Twitter | C5: 45750 | D5: Text | E5: Check out our latest text on twitter! | F5: 4054 | G5: 389 | H5: 493 | I5: 64864 | J5: 64383 | K5: 117 | L5: ModelYCampaign | M5: 0.076097681 | N5: Hashtags Used | O5: #TeslaCoInnovation
A6: P002 | B6: Twitter | C6: 45750 | D6: Text | E6: Check out our latest text on twitter! | F6: 4054 | G6: 389 | H6: 493 | I6: 64864 | J6: 64383 | K6: 117 | L6: ModelYCampaign | M6: 0.076097681 | N6: Hashtags-1 | O6: #BetterWithTesla
A7: P002 | B7: Twitter | C7: 45750 | D7: Text | E7: Check out our latest text on twitter! | F7: 4054 | G7: 389 | H7: 493 | I7: 64864 | J7: 64383 | K7: 117 | L7: ModelYCampaign | M7: 0.076097681 | N7: Hashtags_2 | O7: no data
A8: P003 | B8: YouTube | C8: 45789 | D8: Reel | E8: Check out our latest reel on youtube! | F8: 2795 | G8: 105 | H8: 49 | I8: 53105 | J8: 52307 | K8: 204 | L8: FSDUpdate | M8: 0.055531494 | N8: Hashtags Used | O8: #TeslaCoInnovation
A9: P003 | B9: YouTube | C9: 45789 | D9: Reel | E9: Check out our latest reel on youtube! | F9: 2795 | G9: 105 | H9: 49 | I9: 53105 | J9: 52307 | K9: 204 | L9: FSDUpdate | M9: 0.055531494 | N9: Hashtags-1 | O9: no data
A10: P003 | B10: YouTube | C10: 45789 | D10: Reel | E10: Check out our latest reel on youtube! | F10: 2795 | G10: 105 | H10: 49 | I10: 53105 | J10: 52307 | K10: 204 | L10: FSDUpdate | M10: 0.055531494 | N10: Hashtags_2 | O10: no data
A11: P004 | B11: Instagram | C11: 45516 | D11: Story | E11: Check out our latest story on instagram! | F11: 2404 | G11: 363 | H11: 138 | I11: 19232 | J11: 18636 | K11: 128 | L11: SustainabilityDrive | M11: 0.15105033 | N11: Hashtags Used | O11: #EVRevolution
A12: P004 | B12: Instagram | C12: 45516 | D12: Story | E12: Check out our latest story on instagram! | F12: 2404 | G12: 363 | H12: 138 | I12: 19232 | J12: 18636 | K12: 128 | L12: SustainabilityDrive | M12: 0.15105033 | N12: Hashtags-1 | O12: no data
A13: P004 | B13: Instagram | C13: 45516 | D13: Story | E13: Check out our latest story on instagram! | F13: 2404 | G13: 363 | H13: 138 | I13: 19232 | J13: 18636 | K13: 128 | L13: SustainabilityDrive | M13: 0.15105033 | N13: Hashtags_2 | O13: no data
... A901: P300 | B901: Twitter | C901: 45535 | D901: Carousel | E901: Check out our latest carousel on twitter! | F901: 4494 | G901: 717 | H901: 45 | I901: 62916 | J901: 62688 | K901: 191 | L901: CybertruckLaunch | M901: 0.083539958 | N901: Hashtags_2 | O901: #BetterWithTesla

Sheet Task_4.2
C3: Average performance of posts containing each hashtag
B9: Row Labels | C9: Average of Engagement rate
B10: #TeslaCoInnovation | C10: 0.14471339
B11: #FutureOfDriving | C11: 0.13857977
B12: #BetterWithTesla | C12: 0.13494405
B13: #SmoothLikeNitroTesla | C13: 0.1156632
B14: #AnytimeIsTeslaTime | C14: 0.11063721
B26: #EVRevolution generated the highest engagement rate, suggesting strong audience interest in sustainability and innovation themes,
B27: followed by #TeslaCoInnovation and #FutureOfDriving.
B28: This shows that posts focusing on electric vehicle innovation and future mobility themes resonate most strongly with Tesla’s audience.
B29: Hashtags centered on innovation and technology generate greater user interaction compared to product-specific tags like #Cybertruck or #ModelY.

Sheet Task_4.3
E3: Content performance(Videos vs Image vs Carousel)
C12: Row Labels | D12: Average of Engagement rate
C13: Carousel | D13: 0.15130647
C14: Video | D14: 0.1417139
C15: Image | D15: 0.14055106
C16: Text | D16: 0.11493409
B25: Both Carousels and Videos achieved the highest average engagement rate (14.8%), followed by Images.
B26: This indicates that Tesla’s audience responds equally well to interactive visual content (Carousels highlighting features and comparisons) and dynamic video content (e.g. product demos).
B27: Images, while performing decently, generate relatively lower engagement, suggesting Tesla should continue prioritizing video and carousel formats for future campaigns.

Sheet Task_4.4
B3: Content type priorities per platform recommendation
A10: Average of Engagement rate | B10: Column Labels | J10: Platform | K10: Highest Performing Content type | L10: Engagement Rate
A11: Row Labels | B11: Carousel | C11: Image | D11: Text | E11: Video | I11: Select Platform | J11: YouTube | K11: =INDEX(B11:G11,MATCH(L11,INDEX(B12:G15,MATCH(J11,A12:A15,0),0),0)) -> Carousel | L11: =MAX(INDEX(B12:G15,MATCH(J11,A12:A15,0),0)) -> 0.18072947
A12: Facebook | B12: 0.12389389 | C12: 0.12381317 | D12: 0.11081401 | E12: 0.12954225
A13: Instagram | B13: 0.15376945 | C13: 0.14174672 | D13: 0.13157024 | E13: 0.21903796
A14: Twitter | B14: 0.14734283 | C14: 0.15294044 | D14: 0.10484082 | E14: 0.1147814
A15: YouTube | B15: 0.18072947 | C15: 0.15832396 | D15: 0.12012602 | E15: 0.12521483
B19: Tesla should adopt a platform-specific content strategy:
B20: * Use Reels and Stories to drive engagement on Instagram and Twitter.
B21: * Use Text + Image posts on Facebook for informative storytelling.
B22: * Use Carousel-style playlists or feature showcases on YouTube for detailed product comparisons.

Sheet Posts
A1: Post ID | B1: Platform | C1: Date | D1: Content Type | E1: Post Text | F1: Likes | G1: Shares | H1: Comments | I1: Impressions | J1: Reach | K1: Clicks | L1: Hashtags Used | M1: Hashtags-1 | N1: Hashtags_2 | O1: Campaign_Name | P1: Engagement rate | Q1: Period
A2: P001 | B2: Twitter | C2: 45649 | D2: Reel | E2: Check out our latest reel on twitter! | F2: 1461 | G2: 184 | H2: 344 | I2: 21915 | J2: 21675 | K2: 15 | L2: #FutureOfDriving | M2: #AnytimeIsTeslaTime | N2: no data | O2: CybertruckLaunch | P2: =(Table1_149[[#This Row],[Likes]]+Table1_149[[#This Row],[Shares]]+Table1_149[[#This Row],[Comments]])/Table1_149[[#This Row],[Impressions]] -> 0.090759754 | Q2: =IF(O:O="CybertruckLaunch", IF(AND(C:C>=DATE(2024,10,15),C:C<=DATE(2024,11,10)),"During", IF(C:C<DATE(2024,10,15),"Before","After")), IF(O:O="ModelYCampaign", IF(AND(C:C>=DATE(2025,3,1),C:C<=DATE(2025,3,20)),"During", IF(C:C<DATE(2025,3,1),"Before","After")), IF(O:O="SustainabilityDrive", IF(AND(C:C>=DATE(2024,6,10),C:C<=DATE(2024,6,25)),"During", IF(C:C<DATE(2024,6,10),"Before","After")), IF(O:O="FSDUpdate", IF(AND(C:C>=DATE(2025,5,1),C:C<=DATE(2025,5,15)),"During", IF(C:C<DATE(2025,5,1),"Before","After")))))) -> After
A3: P002 | B3: Twitter | C3: 45750 | D3: Text | E3: Check out our latest text on twitter! | F3: 4054 | G3: 389 | H3: 493 | I3: 64864 | J3: 64383 | K3: 117 | L3: #TeslaCoInnovation | M3: #BetterWithTesla | N3: no data | O3: ModelYCampaign | P3: =(Table1_149[[#This Row],[Likes]]+Table1_149[[#This Row],[Shares]]+Table1_149[[#This Row],[Comments]])/Table1_149[[#This Row],[Impressions]] -> 0.076097681 | Q3: =IF(O:O="CybertruckLaunch", IF(AND(C:C>=DATE(2024,10,15),C:C<=DATE(2024,11,10)),"During", IF(C:C<DATE(2024,10,15),"Before","After")), IF(O:O="ModelYCampaign", IF(AND(C:C>=DATE(2025,3,1),C:C<=DATE(2025,3,20)),"During", IF(C:C<DATE(2025,3,1),"Before","After")), IF(O:O="SustainabilityDrive", IF(AND(C:C>=DATE(2024,6,10),C:C<=DATE(2024,6,25)),"During", IF(C:C<DATE(2024,6,10),"Before","After")), IF(O:O="FSDUpdate", IF(AND(C:C>=DATE(2025,5,1),C:C<=DATE(2025,5,15)),"During", IF(C:C<DATE(2025,5,1),"Before","After")))))) -> After
A4: P003 | B4: YouTube | C4: 45789 | D4: Reel | E4: Check out our latest reel on youtube! | F4: 2795 | G4: 105 | H4: 49 | I4: 53105 | J4: 52307 | K4: 204 | L4: #TeslaCoInnovation | M4: no data | N4: no data | O4: FSDUpdate | P4: =(Table1_149[[#This Row],[Likes]]+Table1_149[[#This Row],[Shares]]+Table1_149[[#This Row],[Comments]])/Table1_149[[#This Row],[Impressions]] -> 0.055531494 | Q4: =IF(O:O="CybertruckLaunch", IF(AND(C:C>=DATE(2024,10,15),C:C<=DATE(2024,11,10)),"During", IF(C:C<DATE(2024,10,15),"Before","After")), IF(O:O="ModelYCampaign", IF(AND(C:C>=DATE(2025,3,1),C:C<=DATE(2025,3,20)),"During", IF(C:C<DATE(2025,3,1),"Before","After")), IF(O:O="SustainabilityDrive", IF(AND(C:C>=DATE(2024,6,10),C:C<=DATE(2024,6,25)),"During", IF(C:C<DATE(2024,6,10),"Before","After")), IF(O:O="FSDUpdate", IF(AND(C:C>=DATE(2025,5,1),C:C<=DATE(2025,5,15)),"During", IF(C:C<DATE(2025,5,1),"Before","After")))))) -> During
A5: P004 | B5: Instagram | C5: 45516 | D5: Story | E5: Check out our latest story on instagram! | F5: 2404 | G5: 363 | H5: 138 | I5: 19232 | J5: 18636 | K5: 128 | L5: #EVRevolution | M5: no data | N5: no data | O5: SustainabilityDrive | P5: =(Table1_149[[#This Row],[Likes]]+Table1_149[[#This Row],[Shares]]+Table1_149[[#This Row],[Comments]])/Table1_149[[#This Row],[Impressions]] -> 0.15105033 | Q5: =IF(O:O="CybertruckLaunch", IF(AND(C:C>=DATE(2024,10,15),C:C<=DATE(2024,11,10)),"During", IF(C:C<DATE(2024,10,15),"Before","After")), IF(O:O="ModelYCampaign", IF(AND(C:C>=DATE(2025,3,1),C:C<=DATE(2025,3,20)),"During", IF(C:C<DATE(2025,3,1),"Before","After")), IF(O:O="SustainabilityDrive", IF(AND(C:C>=DATE(2024,6,10),C:C<=DATE(2024,6,25)),"During", IF(C:C<DATE(2024,6,10),"Before","After")), IF(O:O="FSDUpdate", IF(AND(C:C>=DATE(2025,5,1),C:C<=DATE(2025,5,15)),"During", IF(C:C<DATE(2025,5,1),"Before","After")))))) -> After
A6: P005 | B6: YouTube | C6: 45469 | D6: Reel | E6: Check out our latest reel on youtube! | F6: 3557 | G6: 687 | H6: 424 | I6: 71140 | J6: 70701 | K6: 224 | L6: #EVRevolution | M6: #TeslaCoInnovation | N6: no data | O6: CybertruckLaunch | P6: =(Table1_149[[#This Row],[Likes]]+Table1_149[[#This Row],[Shares]]+Table1_149[[#This Row],[Comments]])/Table1_149[[#This Row],[Impressions]] -> 0.065617093 | Q6: =IF(O:O="CybertruckLaunch", IF(AND(C:C>=DATE(2024,10,15),C:C<=DATE(2024,11,10)),"During", IF(C:C<DATE(2024,10,15),"Before","After")), IF(O:O="ModelYCampaign", IF(AND(C:C>=DATE(2025,3,1),C:C<=DATE(2025,3,20)),"During", IF(C:C<DATE(2025,3,1),"Before","After")), IF(O:O="SustainabilityDrive", IF(AND(C:C>=DATE(2024,6,10),C:C<=DATE(2024,6,25)),"During", IF(C:C<DATE(2024,6,10),"Before","After")), IF(O:O="FSDUpdate", IF(AND(C:C>=DATE(2025,5,1),C:C<=DATE(2025,5,15)),"During", IF(C:C<DATE(2025,5,1),"Before","After")))))) -> Before
A7: P006 | B7: Facebook | C7: 45596 | D7: Carousel | E7: Check out our latest carousel on facebook! | F7: 2945 | G7: 930 | H7: 355 | I7: 23560 | J7: 23275 | K7: 256 | L7: #TeslaCoInnovation | M7: no data | N7: no data | O7: ModelYCampaign | P7: =(Table1_149[[#This Row],[Likes]]+Table1_149[[#This Row],[Shares]]+Table1_149[[#This Row],[Comments]])/Table1_149[[#This Row],[Impressions]] -> 0.1795416 | Q7: =IF(O:O="CybertruckLaunch", IF(AND(C:C>=DATE(2024,10,15),C:C<=DATE(2024,11,10)),"During", IF(C:C<DATE(2024,10,15),"Before","After")), IF(O:O="ModelYCampaign", IF(AND(C:C>=DATE(2025,3,1),C:C<=DATE(2025,3,20)),"During", IF(C:C<DATE(2025,3,1),"Before","After")), IF(O:O="SustainabilityDrive", IF(AND(C:C>=DATE(2024,6,10),C:C<=DATE(2024,6,25)),"During", IF(C:C<DATE(2024,6,10),"Before","After")), IF(O:O="FSDUpdate", IF(AND(C:C>=DATE(2025,5,1),C:C<=DATE(2025,5,15)),"During", IF(C:C<DATE(2025,5,1),"Before","After")))))) -> Before
